Workbook

Sheet Simulateur
B1: Simulateur de facture électrique | E1: Fonctionnement du simulateur
E2: Pour utiliser le simulateur il faut compléter les cellules en JAUNE dans les 3 feuilles de calcules (Simulateur, Base de données et tarifs)
A8: Cette page est l'interface où vous saisissez vos données et voyez le résultat. Veuillez compléter les cellules en JAUNE
D9: Cellule à compléter
A11: Informations
A12: Surface en m2 | B12: 40
A13: Nombre d'occupants | B13: 2
A14: Qualité de l'isolation | B14: RE2020 (récente)
A15: Type d'énergie | B15: Electrique et gaz
A16: Type de contrat | B16: HP/HC
A17: Tye de plaques de cuisson | B17: Electrique
A19: Electricité | C19: Gaz
A20: Consommation/an (kWh) | B20: =Calculs!H6+IF(B15="Tout électrique",Calculs!H10+Calculs!H11,0)+IF(B17="Electrique",'Base de données'!O15,0) -> 4065.36 | C20: Consommation/an (kWh) | D20: =IF(B15="Electrique et gaz", Calculs!H10+Calculs!H11, "N/A")+IF(B17="Gaz",'Base de données'!O15,0) -> 3800
A21: Consommation HP (kWh) | B21: =IF(B16="HP/HC", B20*0.6, "N/A") -> 2439.216
A22: Consommation HC (kWh) | B22: =IF(B16="HP/HC", B20*0.4, "N/A") -> 1626.144
A23: Prix total élec € | B23: =IF(B16="Normal", B20*Tarifs!B11+Tarifs!B14, (B21*Tarifs!B12)+(B22*Tarifs!B13)+Tarifs!B14) -> 923.47539 | C23: Prix total gaz € | D23: =IF(B15="Electrique et gaz", D20*Tarifs!D11+Tarifs!D14, 0) -> 647.1
A24: Prix total élec €/mois | B24: =B23/12 -> 76.956283 | C24: Prix total gaz €/mois | D24: =D23/12 -> 53.925

Sheet Base de données
B1: Simulateur de facture électrique
J5: Ne pas modifier les cellules ci-dessous
A7: Cette feuille correspond aux données nécessaires au fonctionnement du simulateur. Veuillez remplir les colonnes du tableau en JAUNE | J7: Qualité d'isolation | K7: Type d'énergie | L7: Temps d'uitlisation en heure/jour | M7: Nombre de jour par semaine | N7: Type de contrat | O7: Type de plaques de cuisson
J8: Ancienne | K8: Tout électrique | L8: 0 | M8: 0 | N8: Normal | O8: Electrique
J9: RT2012 (moyenne) | K9: Electrique et gaz | L9: 0.1 | M9: 1 | N9: HP/HC | O9: Gaz
A10: Les puissances moyennes et temps d'utilisation de chaque appareil. Ajoutez des appareils si besoin | J10: RE2020 (récente) | L10: 0.2 | M10: 2
L11: 0.3 | M11: 3 | O11: 2000 | P11: Puissance
A12: Appareil | B12: Puissance moyenne (Watts) | C12: Temps d'utilisation en heure/jour | D12: Nombre de jour par semaine | E12: Heure/semaine d'utilisation | F12: Consommation annuelle (kWh) | L12: 0.4 | M12: 4 | O12: 0.5 | P12: temps/j
A13: Réfrigérateur | B13: 150 | C13: 24 | D13: 7 | E13: =Tableau1[[#This Row],[Temps d''utilisation en heure/jour]]*Tableau1[[#This Row],[Nombre de jour par semaine]] -> 168 | F13: =(B13*C13*(D13*52))/1000 -> 1310.4 | L13: 0.5 | M13: 5 | O13: 7 | P13: j/semaine
A14: Lave-linge | B14: 2000 | C14: 1.5 | D14: 4 | E14: =Tableau1[[#This Row],[Temps d''utilisation en heure/jour]]*Tableau1[[#This Row],[Nombre de jour par semaine]] -> 6 | F14: =(B14*C14*(D14*52))/1000 -> 624 | L14: 0.6 | M14: 6 | O14: =O12*O13 -> 3.5 | P14: total/semaine
A15: Sèche-linge | B15: 2500 | C15: 1.5 | D15: 2 | E15: =Tableau1[[#This Row],[Temps d''utilisation en heure/jour]]*Tableau1[[#This Row],[Nombre de jour par semaine]] -> 3 | F15: =(B15*C15*(D15*52))/1000 -> 390 | L15: 0.7 | M15: 7 | O15: =(O11*O12*(O13*52))/1000 -> 364 | P15: conso kWh
A16: Lave-vaisselle | B16: 1200 | C16: 1.5 | D16: 5 | E16: =Tableau1[[#This Row],[Temps d''utilisation en heure/jour]]*Tableau1[[#This Row],[Nombre de jour par semaine]] -> 7.5 | F16: =(B16*C16*(D16*52))/1000 -> 468 | L16: 0.8
A17: Micro-onde | B17: 1000 | C17: 0.2 | D17: 5 | E17: =Tableau1[[#This Row],[Temps d''utilisation en heure/jour]]*Tableau1[[#This Row],[Nombre de jour par semaine]] -> 1 | F17: =(B17*C17*(D17*52))/1000 -> 52 | L17: 0.9
A18: Four électrique | B18: 2500 | C18: 1 | D18: 2 | E18: =Tableau1[[#This Row],[Temps d''utilisation en heure/jour]]*Tableau1[[#This Row],[Nombre de jour par semaine]] -> 2 | F18: =(B18*C18*(D18*52))/1000 -> 260 | L18: 1
A19: Bouilloire | B19: 2000 | C19: 0.1 | D19: 7 | E19: =Tableau1[[#This Row],[Temps d''utilisation en heure/jour]]*Tableau1[[#This Row],[Nombre de jour par semaine]] -> 0.7 | F19: =(B19*C19*(D19*52))/1000 -> 72.8 | L19: 1.1
A20: TV (LED) | B20: 100 | C20: 4 | D20: 5 | E20: =Tableau1[[#This Row],[Temps d''utilisation en heure/jour]]*Tableau1[[#This Row],[Nombre de jour par semaine]] -> 20 | F20: =(B20*C20*(D20*52))/1000 -> 104 | L20: 1.2
A21: Ampoule LED (total) | B21: 90 | C21: 5 | D21: 7 | E21: =Tableau1[[#This Row],[Temps d''utilisation en heure/jour]]*Tableau1[[#This Row],[Nombre de jour par semaine]] -> 35 | F21: =(B21*C21*(D21*52))/1000 -> 163.8 | L21: 1.3
A22: Ordinateur Portable | B22: 60 | C22: 6 | D22: 5 | E22: =Tableau1[[#This Row],[Temps d''utilisation en heure/jour]]*Tableau1[[#This Row],[Nombre de jour par semaine]] -> 30 | F22: =(B22*C22*(D22*52))/1000 -> 93.6 | L22: 1.4
A23: Box internet | B23: 10 | C23: 24 | D23: 7 | E23: =Tableau1[[#This Row],[Temps d''utilisation en heure/jour]]*Tableau1[[#This Row],[Nombre de jour par semaine]] -> 168 | F23: =(B23*C23*(D23*52))/1000 -> 87.36 | L23: 1.5
A24: Aspirateur | B24: 800 | C24: 0.5 | D24: 1 | E24: =Tableau1[[#This Row],[Temps d''utilisation en heure/jour]]*Tableau1[[#This Row],[Nombre de jour par semaine]] -> 0.5 | F24: =(B24*C24*(D24*52))/1000 -> 20.8 | L24: 1.6
A25: Sèche cheveux | B25: 1500 | C25: 0.1 | D25: 7 | E25: =Tableau1[[#This Row],[Temps d''utilisation en heure/jour]]*Tableau1[[#This Row],[Nombre de jour par semaine]] -> 0.7 | F25: =(B25*C25*(D25*52))/1000 -> 54.6 | L25: 1.7
E26: =Tableau1[[#This Row],[Temps d''utilisation en heure/jour]]*Tableau1[[#This Row],[Nombre de jour par semaine]] -> 0 | F26: =(B26*C26*(D26*52))/1000 -> 0 | L26: 1.8
E27: =Tableau1[[#This Row],[Temps d''utilisation en heure/jour]]*Tableau1[[#This Row],[Nombre de jour par semaine]] -> 0 | F27: =(B27*C27*(D27*52))/1000 -> 0 | L27: 1.9
E28: =Tableau1[[#This Row],[Temps d''utilisation en heure/jour]]*Tableau1[[#This Row],[Nombre de jour par semaine]] -> 0 | F28: =(B28*C28*(D28*52))/1000 -> 0 | L28: 2
E29: =Tableau1[[#This Row],[Temps d''utilisation en heure/jour]]*Tableau1[[#This Row],[Nombre de jour par semaine]] -> 0 | F29: =(B29*C29*(D29*52))/1000 -> 0 | L29: 2.1
E30: =Tableau1[[#This Row],[Temps d''utilisation en heure/jour]]*Tableau1[[#This Row],[Nombre de jour par semaine]] -> 0 | F30: =(B30*C30*(D30*52))/1000 -> 0 | L30: 2.2
E31: =Tableau1[[#This Row],[Temps d''utilisation en heure/jour]]*Tableau1[[#This Row],[Nombre de jour par semaine]] -> 0 | F31: =(B31*C31*(D31*52))/1000 -> 0 | L31: 2.3
E32: =Tableau1[[#This Row],[Temps d''utilisation en heure/jour]]*Tableau1[[#This Row],[Nombre de jour par semaine]] -> 0 | F32: =(B32*C32*(D32*52))/1000 -> 0 | L32: 2.4
E33: =Tableau1[[#This Row],[Temps d''utilisation en heure/jour]]*Tableau1[[#This Row],[Nombre de jour par semaine]] -> 0 | F33: =(B33*C33*(D33*52))/1000 -> 0 | L33: 2.5
E34: =Tableau1[[#This Row],[Temps d''utilisation en heure/jour]]*Tableau1[[#This Row],[Nombre de jour par semaine]] -> 0 | F34: =(B34*C34*(D34*52))/1000 -> 0 | L34: 2.6
E35: =Tableau1[[#This Row],[Temps d''utilisation en heure/jour]]*Tableau1[[#This Row],[Nombre de jour par semaine]] -> 0 | F35: =(B35*C35*(D35*52))/1000 -> 0 | L35: 2.7
E36: =Tableau1[[#This Row],[Temps d''utilisation en heure/jour]]*Tableau1[[#This Row],[Nombre de jour par semaine]] -> 0 | F36: =(B36*C36*(D36*52))/1000 -> 0 | L36: 2.8
E37: =Tableau1[[#This Row],[Temps d''utilisation en heure/jour]]*Tableau1[[#This Row],[Nombre de jour par semaine]] -> 0 | F37: =(B37*C37*(D37*52))/1000 -> 0 | L37: 2.9
... E48: =Tableau1[[#This Row],[Temps d''utilisation en heure/jour]]*Tableau1[[#This Row],[Nombre de jour par semaine]] -> 0 | F48: =(B48*C48*(D48*52))/1000 -> 0 | L48: 4
L49: 4.1
L50: 4.2
L51: 4.3
L52: 4.4
L53: 4.5
L54: 4.6
...

Sheet Tarifs
B1: Simulateur de facture électrique
A6: Les prix du kWh selon les fournisseurs. Veuillez modifier les prix des cases en Jaune si vous les avez
D7: Cellule à compléter
A9: Electricité | C9: Gaz
A10: Contrat | B10: Prix €/kWh | C10: Contrat | D10: Prix €/kWh
A11: Normal | B11: 0.1952 | C11: Gaz | D11: 0.1045
A12: HP | B12: 0.2081
A13: HC | B13: 0.1635
A14: Abonnement €/an | B14: 150 | C14: Abonnement €/an | D14: 250

Sheet Calculs
A1: Cette page est la partie "cachée" qui fait les opérations. Ne pas modifier les formules
A6: Formule convertion puissance en consommation annuelle | G6: Résultat conso annuelle= | H6: =SUM(Tableau1[Consommation annuelle (kWh)]) -> 3701.36
A7: E = (P * h * j)/1000 | G7: (sans plaques)
A10: Formule calcule conso total avec chauffage | G10: Résultat chauffage | H10: =(Simulateur!B12*IF(Simulateur!B14="Ancienne", 150, IF(Simulateur!B14="RT2012 (moyenne)", 100, 50))) -> 2000
A11: Explication : On prend le total des appareils + (la surface *un coefficient qui dépend de l'isolation : 150 kWh/m²/an pour l'ancien, 100 kWh/m²/an pour le moyen, 50 kWh/m²/an pour le neuf)+ nb d'occupant * 900 kWhpour couvrir l'eau chaude et l'usage courant par personne. | G11: Résultat Eau chaude | H11: =Simulateur!B13*900 -> 1800
A17: Poste de dépense | B17: Consommation | C17: Prix
A18: Chauffage | B18: =Simulateur!B12 * IF(Simulateur!B14="Ancienne", 150, IF(Simulateur!B14="RT2012 (moyenne)", 100, 50)) -> 2000 | C18: =IF(Simulateur!B15="Electrique et gaz", Tableau2[[#This Row],[Consommation]]*Tarifs!D11, IF(Simulateur!B16="Normal", Tableau2[[#This Row],[Consommation]]*Tarifs!B11, Tableau2[[#This Row],[Consommation]]*(0.6*Tarifs!B12+0.4*Tarifs!B13))) -> 209
A19: Eau chaude | B19: =Simulateur!B13 * 900 -> 1800 | C19: =IF(Simulateur!B15="Electrique et gaz", Tableau2[[#This Row],[Consommation]]*Tarifs!D11, IF(Simulateur!B16="Normal", Tableau2[[#This Row],[Consommation]]*Tarifs!B11, Tableau2[[#This Row],[Consommation]]*(0.6*Tarifs!B12+0.4*Tarifs!B13))) -> 188.1
A20: Electroménager | B20: =H6 -> 3701.36 | C20: =IF(Simulateur!B16="Normal", Tableau2[[#This Row],[Consommation]]*Tarifs!B11, Tableau2[[#This Row],[Consommation]]*(0.6*Tarifs!B12+0.4*Tarifs!B13)) -> 704.22075
A21: Abonnement élec | B21: =H13 -> 0 | C21: =Tarifs!B14 -> 150
A22: Abonnement gaz | B22: =H14 -> 0 | C22: =IF(Simulateur!B15="Electrique et gaz",Tarifs!D14,"N/A") -> 250
A23: Plaques de cuisson | B23: ='Base de données'!O15 -> 364 | C23: =IF(Simulateur!B17="Electrique", IF(Simulateur!B16="Normal", Tableau2[[#This Row],[Consommation]]*Tarifs!B11, Tableau2[[#This Row],[Consommation]]*(0.6*Tarifs!B12+0.4*Tarifs!B13)), Tableau2[[#This Row],[Consommation]]*Tarifs!D11) -> 69.25464
